Workbook

Sheet Tracker
A1: LeetCode Methodology Tracker
A2: One rolling redo date: after a redo, enter the completion date in Last Redo Done; Next Redo Date updates automatically. Keep this short: Problem → Pattern → Key idea → Mistake → Confidence. Redo only weak problems.
A3: # | B3: Problem | C3: Link | D3: Topic | E3: Pattern | F3: Difficulty | G3: Date Solved | H3: Key Idea | I3: Key Trick | J3: Mistake I Made | K3: Time Complexity | L3: Space Complexity | M3: Confidence | N3: Redo? | O3: Next Redo Date | P3: Last Redo Done | Q3: Status | R3: Notes | S3: Solution Link
A4: =IF(B4="","",ROW()-3) -> 1 | B4: Contains Duplicate | C4: https://leetcode.com/problems/contains-duplicate/ | D4: Arrays | E4: Hash Set | F4: Easy | G4: 46205 | H4: Check if any value appears more than once. | I4: Use a set to detect repeats in O(1) average lookup. | J4: Remember to return True immediately when duplicate is found. | K4: O(n) | L4: O(n) | M4: High | N4: Yes | O4: =IF(OR($B4="",$N4<>"Yes",$G4="",$M4=""),"",IF(AND(ISNUMBER($P4),$P4<=TODAY()),$P4+IF($M4="Low",3,IF($M4="Medium",7,21)),$G4+IF($M4="Low",2,IF($M4="Medium",5,14)))) -> 46265 | P4: 46244 | Q4: Mastered
A5: =IF(B5="","",ROW()-3) -> 2 | B5: Maximum Average Subarray I | C5: https://leetcode.com/problems/maximum-average-subarray-i/ | D5: Arrays | E5: Fixed-size Sliding Window | F5: Easy | G5: 46205 | H5: Maintain sum of exactly k elements while sliding one step. | I5: Add incoming element and subtract outgoing element. | J5: Loop should end at len(nums)-k; update max_sum not misspelled variable. | K5: O(n) | L5: O(1) | M5: High | N5: Yes | O5: =IF(OR($B5="",$N5<>"Yes",$G5="",$M5=""),"",IF(AND(ISNUMBER($P5),$P5<=TODAY()),$P5+IF($M5="Low",3,IF($M5="Medium",7,21)),$G5+IF($M5="Low",2,IF($M5="Medium",5,14)))) -> 46267 | P5: 46246 | Q5: Review | R5: Can be solved using Cumulative Sum Approach in Time Complexity: O(n), Space Complexity: O(n)
A6: =IF(B6="","",ROW()-3) -> 3 | B6: Find Pivot Integer | C6: https://leetcode.com/problems/find-the-pivot-integer/ | D6: Math | E6: Math / Perfect Square | F6: Easy | G6: 46205 | H6: Pivot x exists when x² equals total sum n(n+1)/2. | I6: Use math.isqrt(total) and verify x*x == total. | J6: Avoid float precision issues from sqrt on large values. | K6: O(1) | L6: O(1) | M6: High | N6: Yes | O6: =IF(OR($B6="",$N6<>"Yes",$G6="",$M6=""),"",IF(AND(ISNUMBER($P6),$P6<=TODAY()),$P6+IF($M6="Low",3,IF($M6="Medium",7,21)),$G6+IF($M6="Low",2,IF($M6="Medium",5,14)))) -> 46271 | P6: 46250 | Q6: Review
A7: =IF(B7="","",ROW()-3) -> 4 | B7: Smallest Integer Divisible by K | C7: https://leetcode.com/problems/smallest-integer-divisible-by-k/ | D7: Math | E7: Modulo / Remainder | F7: Medium | G7: 46205 | H7: Build remainder only; full number becomes too large. | I7: remainder = (remainder*10 + 1) % k; check up to k lengths. | J7: A integer cannot be divisible by numbers having factor 2 or 5. | K7: O(k) | L7: O(1) | M7: Medium | N7: Yes | O7: =IF(OR($B7="",$N7<>"Yes",$G7="",$M7=""),"",IF(AND(ISNUMBER($P7),$P7<=TODAY()),$P7+IF($M7="Low",3,IF($M7="Medium",7,21)),$G7+IF($M7="Low",2,IF($M7="Medium",5,14)))) -> 46219 | P7: 46212 | Q7: Review | R7: A repunit (short for "repeated unit") is any positive integer consisting entirely of the digit 1
A8: =IF(B8="","",ROW()-3) -> 5 | B8: Self Dividing Numbers | C8: https://leetcode.com/problems/self-dividing-numbers/ | D8: Math | E8: Digit Extraction | F8: Easy | G8: 46205 | H8: Check every digit of each number. | I8: digit = num % 10 gets digit; num //= 10 removes digit. | J8: Using num %= 10 causes infinite loop; also handle digit == 0. | K8: O(n*d) | L8: O(1) | M8: High | N8: Yes | O8: =IF(OR($B8="",$N8<>"Yes",$G8="",$M8=""),"",IF(AND(ISNUMBER($P8),$P8<=TODAY()),$P8+IF($M8="Low",3,IF($M8="Medium",7,21)),$G8+IF($M8="Low",2,IF($M8="Medium",5,14)))) -> 46233 | P8: 46212 | Q8: Review
A9: =IF(B9="","",ROW()-3) -> 6 | B9: Subarray Sum Equals K | C9: https://leetcode.com/problems/subarray-sum-equals-k/ | D9: Arrays | E9: Prefix Sum + Hash Table | F9: Medium | G9: 46205 | H9: If prefixSum - k appeared before, then the subarray between that earlier point and current index has sum k | I9: Initialize runningSum[0] = 1 to count subarrays starting from index 0 | J9: Do not use sliding window because nums can contain negative numbers | K9: O(n) | L9: O(n) | M9: Medium | N9: Yes | O9: =IF(OR($B9="",$N9<>"Yes",$G9="",$M9=""),"",IF(AND(ISNUMBER($P9),$P9<=TODAY()),$P9+IF($M9="Low",3,IF($M9="Medium",7,21)),$G9+IF($M9="Low",2,IF($M9="Medium",5,14)))) -> 46219 | P9: 46212 | Q9: Review | S9: https://www.youtube.com/watch?v=-SWrz90jCUM
A10: =IF(B10="","",ROW()-3) -> 7 | B10: Product of Array Except Self | C10: https://leetcode.com/problems/product-of-array-except-self/ | D10: Prefix Product + Suffix Product | E10: Prefix Sum | F10: Medium | G10: 46205 | H10: For each index, answer = product of all elements on left × product of all elements on right | I10: Use result array first to store prefix products, then multiply suffix products in reverse | J10: Do not use division; prefix/suffix handles zero cases naturally | K10: O(n) | L10: O(1) | M10: Medium | N10: Yes | O10: =IF(OR($B10="",$N10<>"Yes",$G10="",$M10=""),"",IF(AND(ISNUMBER($P10),$P10<=TODAY()),$P10+IF($M10="Low",3,IF($M10="Medium",7,21)),$G10+IF($M10="Low",2,IF($M10="Medium",5,14)))) -> 46214 | P10: 46207 | Q10: Review
A11: =IF(B11="","",ROW()-3) -> 8 | B11: Two Sum | C11: https://leetcode.com/problems/two-sum/ | D11: Arrays | E11: Hashmap / Frequency | F11: Easy | G11: 46207 | H11: For each number, check whether its required complement was seen earlier | I11: complement = target - val; check before storing the current value | J11: Do not store current number before checking if it could match itself | K11: O(n) | L11: O(n) | M11: High | N11: Yes | O11: =IF(OR($B11="",$N11<>"Yes",$G11="",$M11=""),"",IF(AND(ISNUMBER($P11),$P11<=TODAY()),$P11+IF($M11="Low",3,IF($M11="Medium",7,21)),$G11+IF($M11="Low",2,IF($M11="Medium",5,14)))) -> 46235 | P11: 46214 | Q11: Mastered | R11: Use a HashMap when you need fast lookup of something you have already seen.
A12: =IF(B12="","",ROW()-3) -> 9 | B12: Best Time to Buy and Sell Stock | C12: https://leetcode.com/problems/best-time-to-buy-and-sell-stock/ | D12: Arrays / Dynamic Programming | E12: Greedy / Running Minimum | F12: Easy | G12: 46208 | H12: Track cheapest price seen so far and best profit | I12: Current price is sell; minimum so far is buy | J12: Buy must come before sell; do not use global min/max | K12: O(n) | L12: O(1) | M12: High | N12: Yes | O12: =IF(OR($B12="",$N12<>"Yes",$G12="",$M12=""),"",IF(AND(ISNUMBER($P12),$P12<=TODAY()),$P12+IF($M12="Low",3,IF($M12="Medium",7,21)),$G12+IF($M12="Low",2,IF($M12="Medium",5,14)))) -> 46236 | P12: 46215 | Q12: Mastered | R12: Maximum future gain with order constraint → track minimum so far.
A13: =IF(B13="","",ROW()-3) -> 10 | B13: Find Pivot Index | C13: https://leetcode.com/problems/find-pivot-index/ | D13: Arrays | E13: Prefix Sum + Total Sum | F13: Easy | G13: 46208 | H13: Maintain left sum and right sum while scanning | I13: Remove current element from right before comparing | J13: Pivot element belongs to neither side | K13: O(n) | L13: O(1) | M13: High | N13: Yes | O13: =IF(OR($B13="",$N13<>"Yes",$G13="",$M13=""),"",IF(AND(ISNUMBER($P13),$P13<=TODAY()),$P13+IF($M13="Low",3,IF($M13="Medium",7,21)),$G13+IF($M13="Low",2,IF($M13="Medium",5,14)))) -> 46236 | P13: 46215 | Q13: Mastered | R13: Equal left/right sums around an index → running prefix sum.
A14: =IF(B14="","",ROW()-3) -> 11 | B14: Remove Covered Intervals | G14: 46209 | N14: Yes | O14: =IF(OR($B14="",$N14<>"Yes",$G14="",$M14=""),"",IF(AND(ISNUMBER($P14),$P14<=TODAY()),$P14+IF($M14="Low",3,IF($M14="Medium",7,21)),$G14+IF($M14="Low",2,IF($M14="Medium",5,14)))) | Q14: Review
A15: =IF(B15="","",ROW()-3) -> 12 | B15: Concatenate Non-Zero Digits and Multiply by Sum I | G15: 46209 | N15: Yes | O15: =IF(OR($B15="",$N15<>"Yes",$G15="",$M15=""),"",IF(AND(ISNUMBER($P15),$P15<=TODAY()),$P15+IF($M15="Low",3,IF($M15="Medium",7,21)),$G15+IF($M15="Low",2,IF($M15="Medium",5,14)))) | Q15: Review
A16: =IF(B16="","",ROW()-3) -> 13 | B16: Flood Fill | G16: 46210 | N16: Yes | O16: =IF(OR($B16="",$N16<>"Yes",$G16="",$M16=""),"",IF(AND(ISNUMBER($P16),$P16<=TODAY()),$P16+IF($M16="Low",3,IF($M16="Medium",7,21)),$G16+IF($M16="Low",2,IF($M16="Medium",5,14)))) | Q16: Review
A17: =IF(B17="","",ROW()-3) -> 14 | B17: Concatenate Non-Zero Digits and Multiply by Sum II | C17: https://leetcode.com/problems/concatenate-non-zero-digits-and-multiply-by-sum-ii/ | D17: Strings / Range Queries | E17: Prefix Preprocessing + Modular Arithmetic | F17: Medium | G17: 46211 | H17: Precompute digit sum, non-zero count, and concatenated prefix value. | I17: Remove left prefix using right - left × 10^(digits in range). | J17: Do not build huge integers or rescan every query. | K17: O(n + q) | L17: O(n) | M17: Low | N17: Yes | O17: =IF(OR($B17="",$N17<>"Yes",$G17="",$M17=""),"",IF(AND(ISNUMBER($P17),$P17<=TODAY()),$P17+IF($M17="Low",3,IF($M17="Medium",7,21)),$G17+IF($M17="Low",2,IF($M17="Medium",5,14)))) -> 46213 | Q17: New | R17: Many range queries on unchanged data → preprocess prefixes. Concatenated numeric ranges need prefix value + powers of 10, not string slicing.
A18: =IF(B18="","",ROW()-3) -> 15 | B18: Path Existence Queries in a Graph I | C18: https://leetcode.com/problems/path-existence-queries-in-a-graph-i/ | D18: Graphs | E18: Component Labeling / Preprocessing | F18: Medium | G18: 46212 | H18: Label each connected segment once, then compare component IDs for each query. | I18: Gap > maxDiff starts a new component. | J18: Do not run DFS for every query; preprocess connectivity once. | K18: O(n + q) | L18: O(n) | M18: Low | N18: Yes | O18: =IF(OR($B18="",$N18<>"Yes",$G18="",$M18=""),"",IF(AND(ISNUMBER($P18),$P18<=TODAY()),$P18+IF($M18="Low",3,IF($M18="Medium",7,21)),$G18+IF($M18="Low",2,IF($M18="Medium",5,14)))) -> 46222 | P18: 46219 | Q18: Review | R18: Many connectivity queries on unchanged data → preprocess components once.
A19: =IF(B19="","",ROW()-3) -> 16 | B19: Smallest Subsequence of Distinct Characters | C19: https://leetcode.com/problems/smallest-subsequence-of-distinct-characters/ | F19: Medium | G19: 46222 | O19: =IF(OR($B19="",$N19<>"Yes",$G19="",$M19=""),"",IF(AND(ISNUMBER($P19),$P19<=TODAY()),$P19+IF($M19="Low",3,IF($M19="Medium",7,21)),$G19+IF($M19="Low",2,IF($M19="Medium",5,14))))
A20: =IF(B20="","",ROW()-3) -> 17 | B20: Maximum Product of Two Elements in an Array | C20: https://leetcode.com/problems/maximum-product-of-two-elements-in-an-array/ | D20: Arrays | E20: Tracking Top Two Values / One-pass Greedy | F20: Easy | G20: 46230 | H20: Find the best pair by tracking either top two values or best previous max. | I20: Old firstMax becomes secondMax when new max is found. | J20: Do not miss the case where num is between firstMax and secondMax. | K20: O(n) | L20: O(1) | M20: High | N20: Yes | O20: =IF(OR($B20="",$N20<>"Yes",$G20="",$M20=""),"",IF(AND(ISNUMBER($P20),$P20<=TODAY()),$P20+IF($M20="Low",3,IF($M20="Medium",7,21)),$G20+IF($M20="Low",2,IF($M20="Medium",5,14)))) -> 46244 | Q20: Mastered
A21: =IF(B21="","",ROW()-3) -> 18 | B21: Smallest Palindromic Rearrangement I | C21: https://leetcode.com/problems/smallest-palindromic-rearrangement-i/ | D21: String/Sorting/Counting Sort | E21: Sorting + Two-Pointer / Palindrome Mirroring | F21: Easy | G21: 46232 | H21: Sort only the first half, then mirror it to the second half. | I21: For smallest palindrome, smallest chars must be placed from left to right. | J21: Do not sort whole string; preserve palindrome by mirroring first half. | K21: O(n logn) | L21: O(n) | M21: Medium | N21: Yes | O21: =IF(OR($B21="",$N21<>"Yes",$G21="",$M21=""),"",IF(AND(ISNUMBER($P21),$P21<=TODAY()),$P21+IF($M21="Low",3,IF($M21="Medium",7,21)),$G21+IF($M21="Low",2,IF($M21="Medium",5,14)))) -> 46237 | Q21: New
A22: =IF(B22="","",ROW()-3) -> 19 | B22: Smallest Palindromic Rearrangement II | C22: https://leetcode.com/problems/smallest-palindromic-rearrangement-ii/ | O22: =IF(OR($B22="",$N22<>"Yes",$G22="",$M22=""),"",IF(AND(ISNUMBER($P22),$P22<=TODAY()),$P22+IF($M22="Low",3,IF($M22="Medium",7,21)),$G22+IF($M22="Low",2,IF($M22="Medium",5,14))))
A23: =IF(B23="","",ROW()-3) -> 20 | B23: Minimum Number of Pushes to Type Word I | C23: https://leetcode.com/problems/minimum-number-of-pushes-to-type-word-i | D23: Key Assignment | E23: Greedy | F23: Easy | G23: 46234 | H23: Assign letters round-robin across 8 keys; first 8 cost 1 push, next 8 cost 2 pushes. | I23: Push count depends on position: i // 8 + 1 | J23: If using key numbers 2–9, array size must handle index 9. | K23: O(n) | L23: O(1) | M23: Medium | N23: Yes | O23: =IF(OR($B23="",$N23<>"Yes",$G23="",$M23=""),"",IF(AND(ISNUMBER($P23),$P23<=TODAY()),$P23+IF($M23="Low",3,IF($M23="Medium",7,21)),$G23+IF($M23="Low",2,IF($M23="Medium",5,14)))) -> 46239 | Q23: New | R23: 8 keys + assign letters by position → cost = i // 8 + 1 Word I: frequency does not matter much; assign by position.
A24: =IF(B24="","",ROW()-3) -> 21 | B24: Minimum Number of Pushes to Type Word II | C24: https://leetcode.com/problems/minimum-number-of-pushes-to-type-word-ii | D24: Greedy | E24: Greedy + Frequency Sorting | F24: Medium | G24: 46234 | H24: Count character frequencies and give cheapest press positions to most frequent letters. | I24: Sort frequencies descending; cost group is i // 8 + 1. | J24: Use ord(ch) - ord('a'); Python cannot do ch - 'a'. | K24: O(n + 26 log 26) → O(n) | L24: O(1) | M24: Medium | N24: Yes | O24: =IF(OR($B24="",$N24<>"Yes",$G24="",$M24=""),"",IF(AND(ISNUMBER($P24),$P24<=TODAY()),$P24+IF($M24="Low",3,IF($M24="Medium",7,21)),$G24+IF($M24="Low",2,IF($M24="Medium",5,14)))) -> 46239 | Q24: New | R24: Minimize typing cost → highest frequency gets lowest press count Word II: frequency matters; sort characters by frequency first.
A25: =IF(B25="","",ROW()-3) -> 22 | B25: Predict The Winner | C25: https://leetcode.com/problems/predict-the-winner/ | D25: Dynamic Programming, Game Theory | E25: Interval DP / Minimax Game DP | F25: Medium | G25: 46235 | H25: Choose left/right to maximize Player 1 score | I25: Use min() because opponent leaves worst future state | J25: Add memoization; same (i,j) ranges repeat | K25: O(n²) with memo | L25: O(n²) | M25: Low | N25: Yes | O25: =IF(OR($B25="",$N25<>"Yes",$G25="",$M25=""),"",IF(AND(ISNUMBER($P25),$P25<=TODAY()),$P25+IF($M25="Low",3,IF($M25="Medium",7,21)),$G25+IF($M25="Low",2,IF($M25="Medium",5,14)))) -> 46237 | Q25: New | R25: Two players + pick from ends + optimal play → Interval DP / Minimax.
A26: =IF(B26="","",ROW()-3) -> 23 | B26: Stone Game | C26: https://leetcode.com/problems/stone-game/ | D26: Dynamic Programming, Game Theory | E26: Interval DP / Minimax / Score Difference | F26: Medium | G26: 46235 | H26: Return best score difference for current player from interval. | I26: Take left/right, then subtract opponent’s best future advantage. | J26: memo[(i,j)] stores score difference, not total score. | K26: O(n²) | L26: O(n²) | M26: Medium | N26: Yes | O26: =IF(OR($B26="",$N26<>"Yes",$G26="",$M26=""),"",IF(AND(ISNUMBER($P26),$P26<=TODAY()),$P26+IF($M26="Low",3,IF($M26="Medium",7,21)),$G26+IF($M26="Low",2,IF($M26="Medium",5,14)))) -> 46257 | P26: 46250 | Q26: Review | R26: Two players + pick from ends + optimal play → Interval DP / Minimax. - Shortcut: Alice always wins by choosing better parity group.
A27: =IF(B27="","",ROW()-3) -> 24 | B27: Valid Anagram | C27: https://leetcode.com/problems/valid-anagram/ | D27: HashTable | E27: HashMap / Frequency Counting | F27: Easy | G27: 46235 | H27: Count characters in both strings and compare frequencies. | I27: Same characters must have same counts. | J27: Check length first; anagram needs equal total length. | K27: O(n) | L27: O(1) | M27: High | N27: Yes | O27: =IF(OR($B27="",$N27<>"Yes",$G27="",$M27=""),"",IF(AND(ISNUMBER($P27),$P27<=TODAY()),$P27+IF($M27="Low",3,IF($M27="Medium",7,21)),$G27+IF($M27="Low",2,IF($M27="Medium",5,14)))) -> 46274 | P27: 46253 | Q27: Mastered | R27: Anagram/permutation check → character frequency map.
A28: =IF(B28="","",ROW()-3) -> 25 | B28: Majority Element | C28: https://leetcode.com/problems/majority-element/ | D28: HashTable | E28: HashMap / Frequency Counting | F28: Easy | G28: 46235 | H28: Count each number and return one with count > n/2. | I28: Majority threshold is len(nums)//2. | J28: Use HashMap when count matters, not just existence. | K28: O(n) | L28: O(n) | M28: High | N28: Yes | O28: =IF(OR($B28="",$N28<>"Yes",$G28="",$M28=""),"",IF(AND(ISNUMBER($P28),$P28<=TODAY()),$P28+IF($M28="Low",3,IF($M28="Medium",7,21)),$G28+IF($M28="Low",2,IF($M28="Medium",5,14)))) -> 46249 | Q28: Mastered | R28: There is also an optimal Boyer-Moore Voting solution with O(1) space.
A29: =IF(B29="","",ROW()-3) -> 26 | B29: Stone Game III | O29: =IF(OR($B29="",$N29<>"Yes",$G29="",$M29=""),"",IF(AND(ISNUMBER($P29),$P29<=TODAY()),$P29+IF($M29="Low",3,IF($M29="Medium",7,21)),$G29+IF($M29="Low",2,IF($M29="Medium",5,14))))
A30: =IF(B30="","",ROW()-3) -> 27 | B30: Find Missing Elements | C30: https://leetcode.com/problems/find-missing-elements/ | O30: =IF(OR($B30="",$N30<>"Yes",$G30="",$M30=""),"",IF(AND(ISNUMBER($P30),$P30<=TODAY()),$P30+IF($M30="Low",3,IF($M30="Medium",7,21)),$G30+IF($M30="Low",2,IF($M30="Medium",5,14))))
A31: =IF(B31="","",ROW()-3) -> 28 | B31: Smallest Divisible Digit Product I | C31: https://leetcode.com/problems/smallest-divisible-digit-product-i/ | E31: Digit Extraction + Brute Force Check | F31: Easy | G31: 46240 | H31: Try numbers from n upward and check digit product. | I31: Extract each digit using num % 10, then reduce using num // 10. | J31: Use product * (num % 10), not (product * num) % 10; return after processing all digits. | K31: O(x · d) where x = numbers checked, d = digits per number | L31: O(1) | M31: Medium | N31: Yes | O31: =IF(OR($B31="",$N31<>"Yes",$G31="",$M31=""),"",IF(AND(ISNUMBER($P31),$P31<=TODAY()),$P31+IF($M31="Low",3,IF($M31="Medium",7,21)),$G31+IF($M31="Low",2,IF($M31="Medium",5,14)))) -> 46245 | R31: Need to inspect digits of a number → use % 10 and // 10.
A32: =IF(B32="","",ROW()-3) -> 29 | B32: Stone Game IV | C32: https://leetcode.com/problems/stone-game-iv/ | D32: Game Theory | E32: 1D Game DP / Memoized Recursion | F32: Hard | G32: 46244 | H32: Current player wins if they can move to any losing state. | I32: Try all square numbers k*k <= n. | J32: Use <=, not <; exact square move is allowed. Add memoization. | K32: O(n√n) | L32: O(n) | M32: Medium | N32: Yes | O32: =IF(OR($B32="",$N32<>"Yes",$G32="",$M32=""),"",IF(AND(ISNUMBER($P32),$P32<=TODAY()),$P32+IF($M32="Low",3,IF($M32="Medium",7,21)),$G32+IF($M32="Low",2,IF($M32="Medium",5,14)))) -> 46249 | Q32: New | R32: Winning state = there exists one move that makes opponent lose.
A33: =IF(B33="","",ROW()-3) -> 30 | B33: Smallest Missing Integer Greater Than Sequential Prefix Sum | C33: https://leetcode.com/problems/smallest-missing-integer-greater-than-sequential-prefix-sum/ | D33: Array, HashSet | E33: Sequential Prefix + Hash Set Lookup | F33: Easy | G33: 46245 | H33: Compute consecutive prefix sum, then find first missing number ≥ sum. | I33: Store nums in set for O(1) membership checks. | J33: Stop prefix as soon as sequence breaks. | K33: O(n) | L33: O(n) | M33: High | N33: Yes | O33: =IF(OR($B33="",$N33<>"Yes",$G33="",$M33=""),"",IF(AND(ISNUMBER($P33),$P33<=TODAY()),$P33+IF($M33="Low",3,IF($M33="Medium",7,21)),$G33+IF($M33="Low",2,IF($M33="Medium",5,14)))) -> 46259 | Q33: New | R33: Sequential prefix sum first, then HashSet search for missing value.
A34: =IF(B34="","",ROW()-3) -> 31 | B34: Length of Longest Subarray With at Most K Frequency | C34: https://leetcode.com/problems/length-of-longest-subarray-with-at-most-k-frequency/ | E34: Sliding Window + HashMap Frequency | F34: Medium | G34: 46246 | H34: Expand right pointer, shrink left when current number frequency exceeds k. | I34: Only nums[j] can become invalid after adding it. | J34: HashMap key should be nums[j], not index j. | K34: O(n) | L34: O(n) | M34: Medium | N34: Yes | O34: =IF(OR($B34="",$N34<>"Yes",$G34="",$M34=""),"",IF(AND(ISNUMBER($P34),$P34<=TODAY()),$P34+IF($M34="Low",3,IF($M34="Medium",7,21)),$G34+IF($M34="Low",2,IF($M34="Medium",5,14)))) -> 46251 | Q34: New | R34: Longest contiguous subarray + frequency limit → Sliding Window + HashMap.
A35: =IF(B35="","",ROW()-3) -> 32 | B35: Range Sum Query - Immutable | C35: https://leetcode.com/problems/range-sum-query-immutable/ | E35: Prefix Sum / Range Query Preprocessing | F35: Easy | G35: 46246 | H35: Precompute cumulative sums to answer range sums fast. | I35: Range sum = preSum[right] - preSum[left-1]. | K35: O(n) init, O(1) per query | L35: O(n) | M35: Medium | N35: Yes | O35: =IF(OR($C35="",$N35<>"Yes",$G35="",$M35=""),"",IF(AND(ISNUMBER($P35),$P35<=TODAY()),$P35+IF($M35="Low",3,IF($M35="Medium",7,21)),$G35+IF($M35="Low",2,IF($M35="Medium",5,14)))) -> 46251 | Q35: New | R35: Many sum queries on unchanged array → prefix sum preprocessing.
A36: =IF(B36="","",ROW()-3) -> 33 | B36: Longest Substring of One Repeating Character | C36: https://leetcode.com/problems/longest-substring-of-one-repeating-character/ | O36: =IF(OR($B36="",$N36<>"Yes",$G36="",$M36=""),"",IF(AND(ISNUMBER($P36),$P36<=TODAY()),$P36+IF($M36="Low",3,IF($M36="Medium",7,21)),$G36+IF($M36="Low",2,IF($M36="Medium",5,14))))
A37: =IF(B37="","",ROW()-3) -> 34 | B37: Longest Subsequence With Non-Zero Bitwise XOR | C37: https://leetcode.com/problems/longest-subsequence-with-non-zero-bitwise-xor/ | D37: Bit Manipulation | F37: Medium | G37: 46249 | H37: If total XOR is non-zero, take all n elements. | I37: If total XOR is zero but some number is non-zero, remove one non-zero element to make XOR non-zero. | J37: If all elements are 0, no non-zero XOR subsequence exists, so return 0. | K37: O(n) | L37: O(1) | M37: Medium | N37: Yes | O37: =IF(OR($B37="",$N37<>"Yes",$G37="",$M37=""),"",IF(AND(ISNUMBER($P37),$P37<=TODAY()),$P37+IF($M37="Low",3,IF($M37="Medium",7,21)),$G37+IF($M37="Low",2,IF($M37="Medium",5,14)))) -> 46254 | Q37: New | R37: Longest subsequence with non-zero XOR → check total XOR and all-zero case.
A38: =IF(B38="","",ROW()-3) -> 35 | B38: Stone Game IX | C38: https://leetcode.com/problems/stone-game-ix/
A39: =IF(B39="","",ROW()-3) -> 36 | B39: Group Anagrams | C39: https://leetcode.com/problems/group-anagrams/ | E39: HashMap + Anagram Signature | F39: Medium | G39: 46253 | H39: Convert each word into a common signature and group words with the same signature. | I39: Anagram signature can be sorted(word) or a 26-count frequency tuple. | J39: Do not use set(word) for anagrams because it ignores character counts. Also, append() returns None. | K39: Sorted key: O(n * m log m); Frequency tuple: O(n * m) | L39: O(n * m) | M39: Medium | N39: Yes | O39: =IF(OR($B39="",$N39<>"Yes",$G39="",$M39=""),"",IF(AND(ISNUMBER($P39),$P39<=TODAY()),$P39+IF($M39="Low",3,IF($M39="Medium",7,21)),$G39+IF($M39="Low",2,IF($M39="Medium",5,14)))) -> 46258 | Q39: Review | R39: I create a signature for each word. All anagrams produce the same signature, so I use that signature as the HashMap key and append the word to that group.
A40: =IF(B40="","",ROW()-3) -> 37 | B40: Distribute Elements Into Two Arrays I | E40: Array Simulation | F40: Easy | G40: 46253 | H40: Maintain two arrays and place each next number based on the last elements. | I40: Compare arr1[-1] and arr2[-1]; append to arr1 only when strictly greater. | J40: In the else case, append to arr2, including when both last elements are equal. | K40: O(n) | L40: O(n) | M40: High | N40: Yes | O40: =IF(OR($B40="",$N40<>"Yes",$G40="",$M40=""),"",IF(AND(ISNUMBER($P40),$P40<=TODAY()),$P40+IF($M40="Low",3,IF($M40="Medium",7,21)),$G40+IF($M40="Low",2,IF($M40="Medium",5,14)))) -> 46267 | Q40: New | R40: Rules directly describe how to build arrays → simulation.
...

Sheet Dashboard
A1: LeetCode Progress Dashboard
A3: Metric | B3: Value | D3: Confidence | E3: Count
A4: Total Problems | B4: =COUNTIF(Tracker!B4:B881,"<>") -> 49 | D4: High | E4: =COUNTIF(Tracker!$M$4:$M$881,D4) -> 16
A5: High Confidence | B5: =COUNTIF(Tracker!M4:M881,"High") -> 16 | D5: Medium | E5: =COUNTIF(Tracker!$M$4:$M$881,D5) -> 20
A6: Medium Confidence | B6: =COUNTIF(Tracker!M4:M881,"Medium") -> 20 | D6: Low | E6: =COUNTIF(Tracker!$M$4:$M$881,D6) -> 4
A7: Low Confidence | B7: =COUNTIF(Tracker!M4:M881,"Low") -> 4
A8: Weak Problems | B8: =COUNTIF(Tracker!Q4:Q881,"Weak") -> 0
A9: Redo Enabled | B9: =COUNTIF(Tracker!N4:N881,"Yes") -> 43
A10: Redo Due / Overdue | B10: =COUNTIFS(Tracker!O4:O881,"<="&TODAY(),Tracker!O4:O881,">0",Tracker!N4:N881,"Yes") -> 37
A12: Redo Queue | B12: Pattern | C12: Confidence | D12: Next Redo Date | E12: Action
A13: =IF(AND(Tracker!$N4="Yes",Tracker!$O4<>"",Tracker!$O4<=TODAY()),Tracker!$B4,"") -> Contains Duplicate | B13: =IF($A13="","",Tracker!$E4) -> Hash Set | C13: =IF($A13="","",Tracker!$M4) -> High | D13: =IF($A13="","",Tracker!$O4) -> 46265 | E13: =IF($A13="","","Redo on paper → enter today in Last Redo Done") -> Redo on paper → enter today in Last Redo Done | H13: =IF(D13="","","Read pattern + key trick; redo if still Low") -> Read pattern + key trick; redo if still Low
A14: =IF(AND(Tracker!$N5="Yes",Tracker!$O5<>"",Tracker!$O5<=TODAY()),Tracker!$B5,"") -> Maximum Average Subarray I | B14: =IF($A14="","",Tracker!$E5) -> Fixed-size Sliding Window | C14: =IF($A14="","",Tracker!$M5) -> High | D14: =IF($A14="","",Tracker!$O5) -> 46267 | E14: =IF($A14="","","Redo on paper → enter today in Last Redo Done") -> Redo on paper → enter today in Last Redo Done | H14: =IF(D14="","","Read pattern + key trick; redo if still Low") -> Read pattern + key trick; redo if still Low
A15: =IF(AND(Tracker!$N6="Yes",Tracker!$O6<>"",Tracker!$O6<=TODAY()),Tracker!$B6,"") -> Find Pivot Integer | B15: =IF($A15="","",Tracker!$E6) -> Math / Perfect Square | C15: =IF($A15="","",Tracker!$M6) -> High | D15: =IF($A15="","",Tracker!$O6) -> 46271 | E15: =IF($A15="","","Redo on paper → enter today in Last Redo Done") -> Redo on paper → enter today in Last Redo Done | H15: =IF(D15="","","Read pattern + key trick; redo if still Low") -> Read pattern + key trick; redo if still Low
A16: =IF(AND(Tracker!$N7="Yes",Tracker!$O7<>"",Tracker!$O7<=TODAY()),Tracker!$B7,"") -> Smallest Integer Divisible by K | B16: =IF($A16="","",Tracker!$E7) -> Modulo / Remainder | C16: =IF($A16="","",Tracker!$M7) -> Medium | D16: =IF($A16="","",Tracker!$O7) -> 46219 | E16: =IF($A16="","","Redo on paper → enter today in Last Redo Done") -> Redo on paper → enter today in Last Redo Done | H16: =IF(D16="","","Read pattern + key trick; redo if still Low") -> Read pattern + key trick; redo if still Low
A17: =IF(AND(Tracker!$N8="Yes",Tracker!$O8<>"",Tracker!$O8<=TODAY()),Tracker!$B8,"") -> Self Dividing Numbers | B17: =IF($A17="","",Tracker!$E8) -> Digit Extraction | C17: =IF($A17="","",Tracker!$M8) -> High | D17: =IF($A17="","",Tracker!$O8) -> 46233 | E17: =IF($A17="","","Redo on paper → enter today in Last Redo Done") -> Redo on paper → enter today in Last Redo Done | H17: =IF(D17="","","Read pattern + key trick; redo if still Low") -> Read pattern + key trick; redo if still Low
A18: =IF(AND(Tracker!$N9="Yes",Tracker!$O9<>"",Tracker!$O9<=TODAY()),Tracker!$B9,"") -> Subarray Sum Equals K | B18: =IF($A18="","",Tracker!$E9) -> Prefix Sum + Hash Table | C18: =IF($A18="","",Tracker!$M9) -> Medium | D18: =IF($A18="","",Tracker!$O9) -> 46219 | E18: =IF($A18="","","Redo on paper → enter today in Last Redo Done") -> Redo on paper → enter today in Last Redo Done | H18: =IF(D18="","","Read pattern + key trick; redo if still Low") -> Read pattern + key trick; redo if still Low
A19: =IF(AND(Tracker!$N10="Yes",Tracker!$O10<>"",Tracker!$O10<=TODAY()),Tracker!$B10,"") -> Product of Array Except Self | B19: =IF($A19="","",Tracker!$E10) -> Prefix Sum | C19: =IF($A19="","",Tracker!$M10) -> Medium | D19: =IF($A19="","",Tracker!$O10) -> 46214 | E19: =IF($A19="","","Redo on paper → enter today in Last Redo Done") -> Redo on paper → enter today in Last Redo Done | H19: =IF(D19="","","Read pattern + key trick; redo if still Low") -> Read pattern + key trick; redo if still Low
A20: =IF(AND(Tracker!$N11="Yes",Tracker!$O11<>"",Tracker!$O11<=TODAY()),Tracker!$B11,"") -> Two Sum | B20: =IF($A20="","",Tracker!$E11) -> Hashmap / Frequency | C20: =IF($A20="","",Tracker!$M11) -> High | D20: =IF($A20="","",Tracker!$O11) -> 46235 | E20: =IF($A20="","","Redo on paper → enter today in Last Redo Done") -> Redo on paper → enter today in Last Redo Done | H20: =IF(D20="","","Read pattern + key trick; redo if still Low") -> Read pattern + key trick; redo if still Low
A21: =IF(AND(Tracker!$N12="Yes",Tracker!$O12<>"",Tracker!$O12<=TODAY()),Tracker!$B12,"") -> Best Time to Buy and Sell Stock | B21: =IF($A21="","",Tracker!$E12) -> Greedy / Running Minimum | C21: =IF($A21="","",Tracker!$M12) -> High | D21: =IF($A21="","",Tracker!$O12) -> 46236 | E21: =IF($A21="","","Redo on paper → enter today in Last Redo Done") -> Redo on paper → enter today in Last Redo Done | H21: =IF(D21="","","Read pattern + key trick; redo if still Low") -> Read pattern + key trick; redo if still Low
A22: =IF(AND(Tracker!$N13="Yes",Tracker!$O13<>"",Tracker!$O13<=TODAY()),Tracker!$B13,"") -> Find Pivot Index | B22: =IF($A22="","",Tracker!$E13) -> Prefix Sum + Total Sum | C22: =IF($A22="","",Tracker!$M13) -> High | D22: =IF($A22="","",Tracker!$O13) -> 46236 | E22: =IF($A22="","","Redo on paper → enter today in Last Redo Done") -> Redo on paper → enter today in Last Redo Done | H22: =IF(D22="","","Read pattern + key trick; redo if still Low") -> Read pattern + key trick; redo if still Low
A24: Rolling Redo Workflow
A25: 1 | B25: Filter Next Redo Date <= today.
A26: 2 | B26: Redo on paper and explain pattern + key trick.
A27: 3 | B27: Enter today's date in Last Redo Done.
A28: 4 | B28: Next Redo Date automatically rolls forward.

Sheet Pattern Guide
A1: Pattern Guide: What to Remember
A3: Pattern | B3: Use When | C3: Core Methodology | D3: Key Lines / Tricks | E3: Example Problems | F3: Common Mistake | G3: Confidence Rule
A4: Hash Set | B4: Need to detect duplicates or membership quickly. | C4: Scan once and store seen values. | D4: if x in seen: return True; seen.add(x) | E4: Contains Duplicate | F4: Using list lookup makes it O(n²). | G4: High if you can explain why lookup is O(1) average.
A5: Fixed-size Sliding Window | B5: Subarray/window size k is fixed. | C5: Compute first window, then slide by +incoming -outgoing. | D5: curr += nums[i+k-1] - nums[i-1] | E5: Maximum Average Subarray I | F5: Wrong loop boundary; recalculating full sum each time. | G5: High if you know last start index is len(nums)-k.
A6: Math / Perfect Square | B6: Problem reduces to equation or number property. | C6: Derive condition first, then verify with integer math. | D6: x = isqrt(total); x*x == total | E6: Find Pivot Integer | F6: Using floats when exact integer check is safer. | G6: High if derivation is clear on paper.
A7: Modulo / Remainder | B7: Number grows huge, but only divisibility matters. | C7: Track remainder instead of full number. | D7: rem = (rem*10 + digit) % k | E7: Smallest Repunit Divisible by K | F7: Trying to build full integer string/number. | G7: High if you can explain why same remainder means same future pattern.
A8: Digit Extraction | B8: Need to inspect digits one by one. | C8: Use modulo for last digit and integer divide to remove it. | D8: digit = num % 10; num //= 10 | E8: Self Dividing Numbers | F8: Using num %= 10 causes infinite loop; forgetting digit 0. | G8: High if you can dry run 128 and 120.
A9: Two Pointers | B9: Sorted array/string or pair from both ends. | C9: Move left/right based on condition. | D9: while l < r: ... | E9: Two Sum II, Valid Palindrome | F9: Moving wrong pointer without reason. | G9: High if pointer movement decision is justified.
A10: Prefix Sum | B10: Need repeated range sums. | C10: Precompute cumulative sums to answer ranges fast. | D10: prefix[i+1] = prefix[i] + nums[i] | E10: Range Sum Query | F10: Off-by-one indexing. | G10: High if range sum formula is automatic.

Sheet Lists
A1: Patterns | C1: Difficulty | E1: Confidence | G1: Yes/No | I1: Done Status | K1: Overall Status
A2: Hash Set | C2: Easy | E2: High | G2: Yes | I2: Pending | K2: New
A3: Hashmap / Frequency | C3: Medium | E3: Medium | G3: No | I3: Done | K3: Review
A4: Fixed-size Sliding Window | C4: Hard | E4: Low | I4: Skipped | K4: Weak
A5: Variable-size Sliding Window | K5: Mastered
A6: Two Pointers
A7: Prefix Sum
A8: Prefix Sum + Total Sum
A9: Prefix Product
A10: Binary Search
A11: Stack
A12: Queue / BFS
A13: DFS / Recursion
A14: Tree DFS
A15: Tree BFS
A16: Graph BFS / DFS
A17: Dynamic Programming
... A33: Tracking Top Two Values / One-pass Greedy

Sheet SQL Tracker
A1: SQL Interview Tracker
A2: Pattern-wise SQL practice: identify the pattern before querying; after solving, explain each major clause and record one mistake/takeaway. Use one rolling redo date for weak questions.
